Traceback (most recent call last):
  File "C:\Users\aless\Documents\projects\image_to_captions\env\lib\site-packages\jupyter_cache\executors\utils.py", line 58, in single_nb_execution
    executenb(
  File "C:\Users\aless\Documents\projects\image_to_captions\env\lib\site-packages\nbclient\client.py", line 1265, in execute
    return NotebookClient(nb=nb, resources=resources, km=km, **kwargs).execute()
  File "C:\Users\aless\Documents\projects\image_to_captions\env\lib\site-packages\jupyter_core\utils\__init__.py", line 166, in wrapped
    return loop.run_until_complete(inner)
  File "c:\users\aless\appdata\local\programs\python\python39\lib\asyncio\base_events.py", line 642, in run_until_complete
    return future.result()
  File "C:\Users\aless\Documents\projects\image_to_captions\env\lib\site-packages\nbclient\client.py", line 703, in async_execute
    await self.async_execute_cell(
  File "C:\Users\aless\Documents\projects\image_to_captions\env\lib\site-packages\nbclient\client.py", line 1021, in async_execute_cell
    await self._check_raise_for_error(cell, cell_index, exec_reply)
  File "C:\Users\aless\Documents\projects\image_to_captions\env\lib\site-packages\nbclient\client.py", line 915, in _check_raise_for_error
    raise CellExecutionError.from_cell_and_msg(cell, exec_reply_content)
nbclient.exceptions.CellExecutionError: An error occurred while executing the following cell:
------------------
import image_to_captions

print(image_to_captions.__version__)
------------------

[1;31m---------------------------------------------------------------------------[0m
[1;31mModuleNotFoundError[0m                       Traceback (most recent call last)
Cell [1;32mIn[1], line 1[0m
[1;32m----> 1[0m [38;5;28;01mimport[39;00m [38;5;21;01mimage_to_captions[39;00m
[0;32m      3[0m [38;5;28mprint[39m(image_to_captions[38;5;241m.[39m__version__)

[1;31mModuleNotFoundError[0m: No module named 'image_to_captions'
ModuleNotFoundError: No module named 'image_to_captions'

